ts_recv,ts_event,rtype,publisher_id,instrument_id,action,side,depth,price,size,flags,ts_in_delta,sequence,bid_px_00,ask_px_00,bid_sz_00,ask_sz_00,bid_ct_00,ask_ct_00,bid_px_01,ask_px_01,bid_sz_01,ask_sz_01,bid_ct_01,ask_ct_01,bid_px_02,ask_px_02,bid_sz_02,ask_sz_02,bid_ct_02,ask_ct_02,bid_px_03,ask_px_03,bid_sz_03,ask_sz_03,bid_ct_03,ask_ct_03,bid_px_04,ask_px_04,bid_sz_04,ask_sz_04,bid_ct_04,ask_ct_04,bid_px_05,ask_px_05,bid_sz_05,ask_sz_05,bid_ct_05,ask_ct_05,bid_px_06,ask_px_06,bid_sz_06,ask_sz_06,bid_ct_06,ask_ct_06,bid_px_07,ask_px_07,bid_sz_07,ask_sz_07,bid_ct_07,ask_ct_07,bid_px_08,ask_px_08,bid_sz_08,ask_sz_08,bid_ct_08,ask_ct_08,bid_px_09,ask_px_09,bid_sz_09,ask_sz_09,bid_ct_09,ask_ct_09,symbol
2025-01-01T00:00:00.000000000Z,2024-12-31T21:59:59.800612945Z,10,1,29307,A,N,0,1.2507,2,168,0,28093558,1.2507,1.2508,11,5,3,2,1.2506,1.2509,21,31,5,6,1.2505,1.251,29,33,5,2,1.2504,1.2511,32,32,4,5,1.2503,1.2512,33,37,6,6,1.2502,1.2513,35,33,2,5,1.2501,1.2514,34,32,5,3,1.25,1.2515,34,34,5,7,1.2499,1.2516,35,32,8,4,1.2498,1.2517,36,52,3,5,6BH5
2025-01-01T22:45:11.822448717Z,2025-01-01T22:45:11.822228593Z,10,1,29307,C,B,0,1.2507,5,130,17854,28100917,1.2507,1.2508,6,5,2,2,1.2506,1.2509,21,31,5,6,1.2505,1.251,29,33,5,2,1.2504,1.2511,32,32,4,5,1.2503,1.2512,33,37,6,6,1.2502,1.2513,35,33,2,5,1.2501,1.2514,34,32,5,3,1.25,1.2515,34,34,5,7,1.2499,1.2516,35,32,8,4,1.2498,1.2517,36,52,3,5,6BH5
2025-01-01T22:45:11.822465275Z,2025-01-01T22:45:11.822357897Z,10,1,29307,C,B,0,1.2507,2,130,12415,28100918,1.2507,1.2508,4,5,1,2,1.2506,1.2509,21,31,5,6,1.2505,1.251,29,33,5,2,1.2504,1.2511,32,32,4,5,1.2503,1.2512,33,37,6,6,1.2502,1.2513,35,33,2,5,1.2501,1.2514,34,32,5,3,1.25,1.2515,34,34,5,7,1.2499,1.2516,35,32,8,4,1.2498,1.2517,36,52,3,5,6BH5
2025-01-01T22:45:11.822879888Z,2025-01-01T22:45:11.822375159Z,10,1,29307,C,B,0,1.2507,4,130,14302,28100919,1.2506,1.2508,21,5,5,2,1.2505,1.2509,29,31,5,6,1.2504,1.251,32,33,4,2,1.2503,1.2511,33,32,6,5,1.2502,1.2512,35,37,2,6,1.2501,1.2513,34,33,5,5,1.25,1.2514,34,32,5,3,1.2499,1.2515,35,34,8,7,1.2498,1.2516,36,32,3,4,1.2497,1.2517,34,52,1,5,6BH5
2025-01-01T22:45:11.822889656Z,2025-01-01T22:45:11.822390595Z,10,1,29307,C,A,0,1.2508,2,130,12664,28100920,1.2506,1.2508,21,3,5,1,1.2505,1.2509,29,31,5,6,1.2504,1.251,32,33,4,2,1.2503,1.2511,33,32,6,5,1.2502,1.2512,35,37,2,6,1.2501,1.2513,34,33,5,5,1.25,1.2514,34,32,5,3,1.2499,1.2515,35,34,8,7,1.2498,1.2516,36,32,3,4,1.2497,1.2517,34,52,1,5,6BH5
2025-01-01T22:45:11.822901898Z,2025-01-01T22:45:11.822406607Z,10,1,29307,C,A,0,1.2508,3,130,12818,28100921,1.2506,1.2509,21,31,5,6,1.2505,1.251,29,33,5,2,1.2504,1.2511,32,32,4,5,1.2503,1.2512,33,37,6,6,1.2502,1.2513,35,33,2,5,1.2501,1.2514,34,32,5,3,1.25,1.2515,34,34,5,7,1.2499,1.2516,35,32,8,4,1.2498,1.2517,36,52,3,5,1.2497,1.2518,34,33,1,5,6BH5
2025-01-01T22:46:41.818303100Z,2025-01-01T22:46:41.818165087Z,10,1,29307,C,B,0,1.2506,4,130,16584,28101191,1.2506,1.2509,17,31,4,6,1.2505,1.251,29,33,5,2,1.2504,1.2511,32,32,4,5,1.2503,1.2512,33,37,6,6,1.2502,1.2513,35,33,2,5,1.2501,1.2514,34,32,5,3,1.25,1.2515,34,34,5,7,1.2499,1.2516,35,32,8,4,1.2498,1.2517,36,52,3,5,1.2497,1.2518,34,33,1,5,6BH5
2025-01-01T22:46:45.818282800Z,2025-01-01T22:46:45.818150099Z,10,1,29307,M,B,0,1.2506,2,130,16901,28101204,1.2506,1.2509,13,31,4,6,1.2505,1.251,29,33,5,2,1.2504,1.2511,32,32,4,5,1.2503,1.2512,33,37,6,6,1.2502,1.2513,35,33,2,5,1.2501,1.2514,34,32,5,3,1.25,1.2515,34,34,5,7,1.2499,1.2516,35,32,8,4,1.2498,1.2517,36,52,3,5,1.2497,1.2518,34,33,1,5,6BH5
2025-01-01T22:46:46.818317693Z,2025-01-01T22:46:46.818190861Z,10,1,29307,C,B,0,1.2506,2,130,18134,28101208,1.2506,1.2509,11,31,3,6,1.2505,1.251,29,33,5,2,1.2504,1.2511,32,32,4,5,1.2503,1.2512,33,37,6,6,1.2502,1.2513,35,33,2,5,1.2501,1.2514,34,32,5,3,1.25,1.2515,34,34,5,7,1.2499,1.2516,35,32,8,4,1.2498,1.2517,36,52,3,5,1.2497,1.2518,34,33,1,5,6BH5
2025-01-01T22:46:47.818429785Z,2025-01-01T22:46:47.818295903Z,10,1,29307,M,B,0,1.2506,2,130,17063,28101212,1.2506,1.2509,8,31,3,6,1.2505,1.251,29,33,5,2,1.2504,1.2511,32,32,4,5,1.2503,1.2512,33,37,6,6,1.2502,1.2513,35,33,2,5,1.2501,1.2514,34,32,5,3,1.25,1.2515,34,34,5,7,1.2499,1.2516,35,32,8,4,1.2498,1.2517,36,52,3,5,1.2497,1.2518,34,33,1,5,6BH5
2025-01-01T22:46:48.818376919Z,2025-01-01T22:46:48.818253127Z,10,1,29307,C,B,0,1.2506,2,130,14629,28101216,1.2506,1.2509,6,31,2,6,1.2505,1.251,29,33,5,2,1.2504,1.2511,32,32,4,5,1.2503,1.2512,33,37,6,6,1.2502,1.2513,35,33,2,5,1.2501,1.2514,34,32,5,3,1.25,1.2515,34,34,5,7,1.2499,1.2516,35,32,8,4,1.2498,1.2517,36,52,3,5,1.2497,1.2518,34,33,1,5,6BH5
2025-01-01T22:46:49.818465250Z,2025-01-01T22:46:49.818342917Z,10,1,29307,M,B,0,1.2506,3,130,16199,28101219,1.2506,1.2509,4,31,2,6,1.2505,1.251,29,33,5,2,1.2504,1.2511,32,32,4,5,1.2503,1.2512,33,37,6,6,1.2502,1.2513,35,33,2,5,1.2501,1.2514,34,32,5,3,1.25,1.2515,34,34,5,7,1.2499,1.2516,35,32,8,4,1.2498,1.2517,36,52,3,5,1.2497,1.2518,34,33,1,5,6BH5
2025-01-01T22:46:50.818562717Z,2025-01-01T22:46:50.818432959Z,10,1,29307,M,B,0,1.2506,2,130,16751,28101222,1.2506,1.2509,3,31,2,6,1.2505,1.251,29,33,5,2,1.2504,1.2511,32,32,4,5,1.2503,1.2512,33,37,6,6,1.2502,1.2513,35,33,2,5,1.2501,1.2514,34,32,5,3,1.25,1.2515,34,34,5,7,1.2499,1.2516,35,32,8,4,1.2498,1.2517,36,52,3,5,1.2497,1.2518,34,33,1,5,6BH5
2025-01-01T22:46:51.818543346Z,2025-01-01T22:46:51.818417439Z,10,1,29307,M,B,0,1.2506,1,130,16507,28101226,1.2506,1.2509,2,31,2,6,1.2505,1.251,29,33,5,2,1.2504,1.2511,32,32,4,5,1.2503,1.2512,33,37,6,6,1.2502,1.2513,35,33,2,5,1.2501,1.2514,34,32,5,3,1.25,1.2515,34,34,5,7,1.2499,1.2516,35,32,8,4,1.2498,1.2517,36,52,3,5,1.2497,1.2518,34,33,1,5,6BH5
2025-01-01T22:46:52.818509209Z,2025-01-01T22:46:52.818391837Z,10,1,29307,C,B,0,1.2506,1,130,16286,28101233,1.2506,1.2509,1,31,1,6,1.2505,1.251,29,33,5,2,1.2504,1.2511,32,32,4,5,1.2503,1.2512,33,37,6,6,1.2502,1.2513,35,33,2,5,1.2501,1.2514,34,32,5,3,1.25,1.2515,34,34,5,7,1.2499,1.2516,35,32,8,4,1.2498,1.2517,36,52,3,5,1.2497,1.2518,34,33,1,5,6BH5
2025-01-01T22:46:53.818613119Z,2025-01-01T22:46:53.818489627Z,10,1,29307,C,B,0,1.2506,1,130,16200,28101235,1.2505,1.2509,29,31,5,6,1.2504,1.251,32,33,4,2,1.2503,1.2511,33,32,6,5,1.2502,1.2512,35,37,2,6,1.2501,1.2513,34,33,5,5,1.25,1.2514,34,32,5,3,1.2499,1.2515,35,34,8,7,1.2498,1.2516,36,32,3,4,1.2497,1.2517,34,52,1,5,1.2496,1.2518,35,33,1,5,6BH5
2025-01-01T22:47:35.819463463Z,2025-01-01T22:47:35.819325331Z,10,1,29307,M,A,0,1.2509,1,130,14976,28101410,1.2505,1.2509,29,25,5,6,1.2504,1.251,32,33,4,2,1.2503,1.2511,33,32,6,5,1.2502,1.2512,35,37,2,6,1.2501,1.2513,34,33,5,5,1.25,1.2514,34,32,5,3,1.2499,1.2515,35,34,8,7,1.2498,1.2516,36,32,3,4,1.2497,1.2517,34,52,1,5,1.2496,1.2518,35,33,1,5,6BH5
2025-01-01T22:47:36.819477793Z,2025-01-01T22:47:36.819358213Z,10,1,29307,C,A,0,1.2509,1,130,14125,28101415,1.2505,1.2509,29,24,5,5,1.2504,1.251,32,33,4,2,1.2503,1.2511,33,32,6,5,1.2502,1.2512,35,37,2,6,1.2501,1.2513,34,33,5,5,1.25,1.2514,34,32,5,3,1.2499,1.2515,35,34,8,7,1.2498,1.2516,36,32,3,4,1.2497,1.2517,34,52,1,5,1.2496,1.2518,35,33,1,5,6BH5
2025-01-01T22:47:36.819487515Z,2025-01-01T22:47:36.819366739Z,10,1,29307,C,A,0,1.2509,4,130,12607,28101416,1.2505,1.2509,29,20,5,4,1.2504,1.251,32,33,4,2,1.2503,1.2511,33,32,6,5,1.2502,1.2512,35,37,2,6,1.2501,1.2513,34,33,5,5,1.25,1.2514,34,32,5,3,1.2499,1.2515,35,34,8,7,1.2498,1.2516,36,32,3,4,1.2497,1.2517,34,52,1,5,1.2496,1.2518,35,33,1,5,6BH5
2025-01-01T22:47:37.819540311Z,2025-01-01T22:47:37.819417927Z,10,1,29307,C,A,0,1.2509,4,130,17104,28101421,1.2505,1.2509,29,16,5,3,1.2504,1.251,32,33,4,2,1.2503,1.2511,33,32,6,5,1.2502,1.2512,35,37,2,6,1.2501,1.2513,34,33,5,5,1.25,1.2514,34,32,5,3,1.2499,1.2515,35,34,8,7,1.2498,1.2516,36,32,3,4,1.2497,1.2517,34,52,1,5,1.2496,1.2518,35,33,1,5,6BH5
2025-01-01T22:47:38.819587403Z,2025-01-01T22:47:38.819451973Z,10,1,29307,C,A,0,1.2509,4,130,17857,28101428,1.2505,1.2509,29,12,5,2,1.2504,1.251,32,33,4,2,1.2503,1.2511,33,32,6,5,1.2502,1.2512,35,37,2,6,1.2501,1.2513,34,33,5,5,1.25,1.2514,34,32,5,3,1.2499,1.2515,35,34,8,7,1.2498,1.2516,36,32,3,4,1.2497,1.2517,34,52,1,5,1.2496,1.2518,35,33,1,5,6BH5
2025-01-01T22:47:39.819612582Z,2025-01-01T22:47:39.819480433Z,10,1,29307,M,A,0,1.2509,1,130,15048,28101433,1.2505,1.2509,29,9,5,2,1.2504,1.251,32,33,4,2,1.2503,1.2511,33,32,6,5,1.2502,1.2512,35,37,2,6,1.2501,1.2513,34,33,5,5,1.25,1.2514,34,32,5,3,1.2499,1.2515,35,34,8,7,1.2498,1.2516,36,32,3,4,1.2497,1.2517,34,52,1,5,1.2496,1.2518,35,33,1,5,6BH5
2025-01-01T22:47:40.819619347Z,2025-01-01T22:47:40.819493165Z,10,1,29307,M,A,0,1.2509,7,130,15684,28101439,1.2505,1.2509,29,8,5,2,1.2504,1.251,32,33,4,2,1.2503,1.2511,33,32,6,5,1.2502,1.2512,35,37,2,6,1.2501,1.2513,34,33,5,5,1.25,1.2514,34,32,5,3,1.2499,1.2515,35,34,8,7,1.2498,1.2516,36,32,3,4,1.2497,1.2517,34,52,1,5,1.2496,1.2518,35,33,1,5,6BH5
2025-01-01T22:47:40.819628923Z,2025-01-01T22:47:40.819505051Z,10,1,29307,C,A,0,1.2509,1,130,13263,28101440,1.2505,1.2509,29,7,5,1,1.2504,1.251,32,33,4,2,1.2503,1.2511,33,32,6,5,1.2502,1.2512,35,37,2,6,1.2501,1.2513,34,33,5,5,1.25,1.2514,34,32,5,3,1.2499,1.2515,35,34,8,7,1.2498,1.2516,36,32,3,4,1.2497,1.2517,34,52,1,5,1.2496,1.2518,35,33,1,5,6BH5
2025-01-01T22:47:40.819638792Z,2025-01-01T22:47:40.819515111Z,10,1,29307,M,B,0,1.2505,3,130,11342,28101441,1.2505,1.2509,23,7,5,1,1.2504,1.251,32,33,4,2,1.2503,1.2511,33,32,6,5,1.2502,1.2512,35,37,2,6,1.2501,1.2513,34,33,5,5,1.25,1.2514,34,32,5,3,1.2499,1.2515,35,34,8,7,1.2498,1.2516,36,32,3,4,1.2497,1.2517,34,52,1,5,1.2496,1.2518,35,33,1,5,6BH5
2025-01-01T22:47:41.819645694Z,2025-01-01T22:47:41.819506469Z,10,1,29307,M,A,0,1.2509,5,130,19257,28101446,1.2505,1.2509,23,5,5,1,1.2504,1.251,32,33,4,2,1.2503,1.2511,33,32,6,5,1.2502,1.2512,35,37,2,6,1.2501,1.2513,34,33,5,5,1.25,1.2514,34,32,5,3,1.2499,1.2515,35,34,8,7,1.2498,1.2516,36,32,3,4,1.2497,1.2517,34,52,1,5,1.2496,1.2518,35,33,1,5,6BH5
2025-01-01T22:47:41.819655739Z,2025-01-01T22:47:41.819517989Z,10,1,29307,C,B,0,1.2505,3,130,13137,28101447,1.2505,1.2509,20,5,4,1,1.2504,1.251,32,33,4,2,1.2503,1.2511,33,32,6,5,1.2502,1.2512,35,37,2,6,1.2501,1.2513,34,33,5,5,1.25,1.2514,34,32,5,3,1.2499,1.2515,35,34,8,7,1.2498,1.2516,36,32,3,4,1.2497,1.2517,34,52,1,5,1.2496,1.2518,35,33,1,5,6BH5
2025-01-01T22:47:41.819663726Z,2025-01-01T22:47:41.819528665Z,10,1,29307,M,B,0,1.2505,2,130,12255,28101448,1.2505,1.2509,18,5,4,1,1.2504,1.251,32,33,4,2,1.2503,1.2511,33,32,6,5,1.2502,1.2512,35,37,2,6,1.2501,1.2513,34,33,5,5,1.25,1.2514,34,32,5,3,1.2499,1.2515,35,34,8,7,1.2498,1.2516,36,32,3,4,1.2497,1.2517,34,52,1,5,1.2496,1.2518,35,33,1,5,6BH5
2025-01-01T22:47:42.819701611Z,2025-01-01T22:47:42.819575719Z,10,1,29307,M,A,0,1.2509,4,130,17062,28101454,1.2505,1.2509,18,4,4,1,1.2504,1.251,32,33,4,2,1.2503,1.2511,33,32,6,5,1.2502,1.2512,35,37,2,6,1.2501,1.2513,34,33,5,5,1.25,1.2514,34,32,5,3,1.2499,1.2515,35,34,8,7,1.2498,1.2516,36,32,3,4,1.2497,1.2517,34,52,1,5,1.2496,1.2518,35,33,1,5,6BH5
2025-01-01T22:47:42.819709782Z,2025-01-01T22:47:42.819586529Z,10,1,29307,C,B,0,1.2505,2,130,11869,28101455,1.2505,1.2509,16,4,3,1,1.2504,1.251,32,33,4,2,1.2503,1.2511,33,32,6,5,1.2502,1.2512,35,37,2,6,1.2501,1.2513,34,33,5,5,1.25,1.2514,34,32,5,3,1.2499,1.2515,35,34,8,7,1.2498,1.2516,36,32,3,4,1.2497,1.2517,34,52,1,5,1.2496,1.2518,35,33,1,5,6BH5
2025-01-01T22:47:42.819719113Z,2025-01-01T22:47:42.819595803Z,10,1,29307,M,B,0,1.2505,2,130,11665,28101456,1.2505,1.2509,14,4,3,1,1.2504,1.251,32,33,4,2,1.2503,1.2511,33,32,6,5,1.2502,1.2512,35,37,2,6,1.2501,1.2513,34,33,5,5,1.25,1.2514,34,32,5,3,1.2499,1.2515,35,34,8,7,1.2498,1.2516,36,32,3,4,1.2497,1.2517,34,52,1,5,1.2496,1.2518,35,33,1,5,6BH5
2025-01-01T22:47:43.819716933Z,2025-01-01T22:47:43.819595439Z,10,1,29307,M,A,0,1.2509,3,130,16568,28101463,1.2505,1.2509,14,3,3,1,1.2504,1.251,32,33,4,2,1.2503,1.2511,33,32,6,5,1.2502,1.2512,35,37,2,6,1.2501,1.2513,34,33,5,5,1.25,1.2514,34,32,5,3,1.2499,1.2515,35,34,8,7,1.2498,1.2516,36,32,3,4,1.2497,1.2517,34,52,1,5,1.2496,1.2518,35,33,1,5,6BH5
2025-01-01T22:47:43.819725711Z,2025-01-01T22:47:43.819605555Z,10,1,29307,M,B,0,1.2505,3,130,12005,28101464,1.2505,1.2509,13,3,3,1,1.2504,1.251,32,33,4,2,1.2503,1.2511,33,32,6,5,1.2502,1.2512,35,37,2,6,1.2501,1.2513,34,33,5,5,1.25,1.2514,34,32,5,3,1.2499,1.2515,35,34,8,7,1.2498,1.2516,36,32,3,4,1.2497,1.2517,34,52,1,5,1.2496,1.2518,35,33,1,5,6BH5
2025-01-01T22:47:43.819739151Z,2025-01-01T22:47:43.819617537Z,10,1,29307,C,B,0,1.2505,2,130,11388,28101465,1.2505,1.2509,11,3,2,1,1.2504,1.251,32,33,4,2,1.2503,1.2511,33,32,6,5,1.2502,1.2512,35,37,2,6,1.2501,1.2513,34,33,5,5,1.25,1.2514,34,32,5,3,1.2499,1.2515,35,34,8,7,1.2498,1.2516,36,32,3,4,1.2497,1.2517,34,52,1,5,1.2496,1.2518,35,33,1,5,6BH5
2025-01-01T22:47:44.819729990Z,2025-01-01T22:47:44.819611105Z,10,1,29307,M,A,0,1.2509,2,130,16171,28101471,1.2505,1.2509,11,2,2,1,1.2504,1.251,32,33,4,2,1.2503,1.2511,33,32,6,5,1.2502,1.2512,35,37,2,6,1.2501,1.2513,34,33,5,5,1.25,1.2514,34,32,5,3,1.2499,1.2515,35,34,8,7,1.2498,1.2516,36,32,3,4,1.2497,1.2517,34,52,1,5,1.2496,1.2518,35,33,1,5,6BH5
2025-01-01T22:47:44.819739113Z,2025-01-01T22:47:44.819622183Z,10,1,29307,C,B,0,1.2505,3,130,12656,28101472,1.2505,1.2509,8,2,1,1,1.2504,1.251,32,33,4,2,1.2503,1.2511,33,32,6,5,1.2502,1.2512,35,37,2,6,1.2501,1.2513,34,33,5,5,1.25,1.2514,34,32,5,3,1.2499,1.2515,35,34,8,7,1.2498,1.2516,36,32,3,4,1.2497,1.2517,34,52,1,5,1.2496,1.2518,35,33,1,5,6BH5
2025-01-01T22:47:45.819749546Z,2025-01-01T22:47:45.819627483Z,10,1,29307,M,A,0,1.2509,1,130,17375,28101478,1.2505,1.2509,8,1,1,1,1.2504,1.251,32,33,4,2,1.2503,1.2511,33,32,6,5,1.2502,1.2512,35,37,2,6,1.2501,1.2513,34,33,5,5,1.25,1.2514,34,32,5,3,1.2499,1.2515,35,34,8,7,1.2498,1.2516,36,32,3,4,1.2497,1.2517,34,52,1,5,1.2496,1.2518,35,33,1,5,6BH5
2025-01-01T22:47:45.819758839Z,2025-01-01T22:47:45.819638407Z,10,1,29307,M,B,0,1.2505,6,130,13039,28101479,1.2505,1.2509,6,1,1,1,1.2504,1.251,32,33,4,2,1.2503,1.2511,33,32,6,5,1.2502,1.2512,35,37,2,6,1.2501,1.2513,34,33,5,5,1.25,1.2514,34,32,5,3,1.2499,1.2515,35,34,8,7,1.2498,1.2516,36,32,3,4,1.2497,1.2517,34,52,1,5,1.2496,1.2518,35,33,1,5,6BH5
2025-01-01T22:47:46.819761593Z,2025-01-01T22:47:46.819636803Z,10,1,29307,C,A,0,1.2509,1,130,16797,28101484,1.2505,1.251,6,33,1,2,1.2504,1.2511,32,32,4,5,1.2503,1.2512,33,37,6,6,1.2502,1.2513,35,33,2,5,1.2501,1.2514,34,32,5,3,1.25,1.2515,34,34,5,7,1.2499,1.2516,35,32,8,4,1.2498,1.2517,36,52,3,5,1.2497,1.2518,34,33,1,5,1.2496,1.2519,35,34,1,4,6BH5
2025-01-01T22:47:46.819770217Z,2025-01-01T22:47:46.819648399Z,10,1,29307,M,B,0,1.2505,4,130,12644,28101485,1.2505,1.251,4,33,1,2,1.2504,1.2511,32,32,4,5,1.2503,1.2512,33,37,6,6,1.2502,1.2513,35,33,2,5,1.2501,1.2514,34,32,5,3,1.25,1.2515,34,34,5,7,1.2499,1.2516,35,32,8,4,1.2498,1.2517,36,52,3,5,1.2497,1.2518,34,33,1,5,1.2496,1.2519,35,34,1,4,6BH5
2025-01-01T22:47:47.819748458Z,2025-01-01T22:47:47.819625751Z,10,1,29307,M,B,0,1.2505,3,130,15459,28101491,1.2505,1.251,3,33,1,2,1.2504,1.2511,32,32,4,5,1.2503,1.2512,33,37,6,6,1.2502,1.2513,35,33,2,5,1.2501,1.2514,34,32,5,3,1.25,1.2515,34,34,5,7,1.2499,1.2516,35,32,8,4,1.2498,1.2517,36,52,3,5,1.2497,1.2518,34,33,1,5,1.2496,1.2519,35,34,1,4,6BH5
2025-01-01T22:47:48.819780538Z,2025-01-01T22:47:48.819647765Z,10,1,29307,M,B,0,1.2505,2,130,19105,28101496,1.2505,1.251,2,33,1,2,1.2504,1.2511,32,32,4,5,1.2503,1.2512,33,37,6,6,1.2502,1.2513,35,33,2,5,1.2501,1.2514,34,32,5,3,1.25,1.2515,34,34,5,7,1.2499,1.2516,35,32,8,4,1.2498,1.2517,36,52,3,5,1.2497,1.2518,34,33,1,5,1.2496,1.2519,35,34,1,4,6BH5
2025-01-01T22:47:49.819733488Z,2025-01-01T22:47:49.819616451Z,10,1,29307,M,B,0,1.2505,1,130,15673,28101501,1.2505,1.251,1,33,1,2,1.2504,1.2511,32,32,4,5,1.2503,1.2512,33,37,6,6,1.2502,1.2513,35,33,2,5,1.2501,1.2514,34,32,5,3,1.25,1.2515,34,34,5,7,1.2499,1.2516,35,32,8,4,1.2498,1.2517,36,52,3,5,1.2497,1.2518,34,33,1,5,1.2496,1.2519,35,34,1,4,6BH5
2025-01-01T22:47:50.819726587Z,2025-01-01T22:47:50.819610191Z,10,1,29307,C,B,0,1.2505,1,130,16214,28101505,1.2504,1.251,32,33,4,2,1.2503,1.2511,33,32,6,5,1.2502,1.2512,35,37,2,6,1.2501,1.2513,34,33,5,5,1.25,1.2514,34,32,5,3,1.2499,1.2515,35,34,8,7,1.2498,1.2516,36,32,3,4,1.2497,1.2517,34,52,1,5,1.2496,1.2518,35,33,1,5,1.2495,1.2519,35,34,1,4,6BH5
2025-01-01T22:48:28.820816671Z,2025-01-01T22:48:28.820681087Z,10,1,29307,M,B,0,1.2504,3,130,15759,28101679,1.2504,1.251,26,33,4,2,1.2503,1.2511,33,32,6,5,1.2502,1.2512,35,37,2,6,1.2501,1.2513,34,33,5,5,1.25,1.2514,34,32,5,3,1.2499,1.2515,35,34,8,7,1.2498,1.2516,36,32,3,4,1.2497,1.2517,34,52,1,5,1.2496,1.2518,35,33,1,5,1.2495,1.2519,35,34,1,4,6BH5
2025-01-01T22:48:29.820873943Z,2025-01-01T22:48:29.820744753Z,10,1,29307,M,B,0,1.2504,2,130,16314,28101687,1.2504,1.251,24,33,4,2,1.2503,1.2511,33,32,6,5,1.2502,1.2512,35,37,2,6,1.2501,1.2513,34,33,5,5,1.25,1.2514,34,32,5,3,1.2499,1.2515,35,34,8,7,1.2498,1.2516,36,32,3,4,1.2497,1.2517,34,52,1,5,1.2496,1.2518,35,33,1,5,1.2495,1.2519,35,34,1,4,6BH5
2025-01-01T22:48:29.820881354Z,2025-01-01T22:48:29.820755063Z,10,1,29307,C,B,0,1.2504,3,130,11788,28101688,1.2504,1.251,21,33,3,2,1.2503,1.2511,33,32,6,5,1.2502,1.2512,35,37,2,6,1.2501,1.2513,34,33,5,5,1.25,1.2514,34,32,5,3,1.2499,1.2515,35,34,8,7,1.2498,1.2516,36,32,3,4,1.2497,1.2517,34,52,1,5,1.2496,1.2518,35,33,1,5,1.2495,1.2519,35,34,1,4,6BH5
2025-01-01T22:48:30.820848654Z,2025-01-01T22:48:30.820718031Z,10,1,29307,C,B,0,1.2504,2,130,16350,28101698,1.2504,1.251,19,33,2,2,1.2503,1.2511,33,32,6,5,1.2502,1.2512,35,37,2,6,1.2501,1.2513,34,33,5,5,1.25,1.2514,34,32,5,3,1.2499,1.2515,35,34,8,7,1.2498,1.2516,36,32,3,4,1.2497,1.2517,34,52,1,5,1.2496,1.2518,35,33,1,5,1.2495,1.2519,35,34,1,4,6BH5
2025-01-01T22:48:30.820857701Z,2025-01-01T22:48:30.820730107Z,10,1,29307,M,B,0,1.2504,3,130,12833,28101699,1.2504,1.251,17,33,2,2,1.2503,1.2511,33,32,6,5,1.2502,1.2512,35,37,2,6,1.2501,1.2513,34,33,5,5,1.25,1.2514,34,32,5,3,1.2499,1.2515,35,34,8,7,1.2498,1.2516,36,32,3,4,1.2497,1.2517,34,52,1,5,1.2496,1.2518,35,33,1,5,1.2495,1.2519,35,34,1,4,6BH5
2025-01-01T22:48:31.820885524Z,2025-01-01T22:48:31.820770663Z,10,1,29307,C,B,0,1.2504,3,130,13819,28101706,1.2504,1.251,14,33,1,2,1.2503,1.2511,33,32,6,5,1.2502,1.2512,35,37,2,6,1.2501,1.2513,34,33,5,5,1.25,1.2514,34,32,5,3,1.2499,1.2515,35,34,8,7,1.2498,1.2516,36,32,3,4,1.2497,1.2517,34,52,1,5,1.2496,1.2518,35,33,1,5,1.2495,1.2519,35,34,1,4,6BH5
2025-01-01T22:48:31.820898741Z,2025-01-01T22:48:31.820789035Z,10,1,29307,M,A,0,1.251,3,130,11944,28101707,1.2504,1.251,14,27,1,2,1.2503,1.2511,33,32,6,5,1.2502,1.2512,35,37,2,6,1.2501,1.2513,34,33,5,5,1.25,1.2514,34,32,5,3,1.2499,1.2515,35,34,8,7,1.2498,1.2516,36,32,3,4,1.2497,1.2517,34,52,1,5,1.2496,1.2518,35,33,1,5,1.2495,1.2519,35,34,1,4,6BH5
2025-01-01T22:48:32.820989961Z,2025-01-01T22:48:32.820860925Z,10,1,29307,M,B,0,1.2504,11,130,17474,28101713,1.2504,1.251,11,27,1,2,1.2503,1.2511,33,32,6,5,1.2502,1.2512,35,37,2,6,1.2501,1.2513,34,33,5,5,1.25,1.2514,34,32,5,3,1.2499,1.2515,35,34,8,7,1.2498,1.2516,36,32,3,4,1.2497,1.2517,34,52,1,5,1.2496,1.2518,35,33,1,5,1.2495,1.2519,35,34,1,4,6BH5
2025-01-01T22:48:32.820999130Z,2025-01-01T22:48:32.820874097Z,10,1,29307,C,A,0,1.251,3,130,13083,28101714,1.2504,1.251,11,24,1,1,1.2503,1.2511,33,32,6,5,1.2502,1.2512,35,37,2,6,1.2501,1.2513,34,33,5,5,1.25,1.2514,34,32,5,3,1.2499,1.2515,35,34,8,7,1.2498,1.2516,36,32,3,4,1.2497,1.2517,34,52,1,5,1.2496,1.2518,35,33,1,5,1.2495,1.2519,35,34,1,4,6BH5
2025-01-01T22:48:32.821009590Z,2025-01-01T22:48:32.820885309Z,10,1,29307,M,A,0,1.251,22,130,12748,28101715,1.2504,1.251,11,22,1,1,1.2503,1.2511,33,32,6,5,1.2502,1.2512,35,37,2,6,1.2501,1.2513,34,33,5,5,1.25,1.2514,34,32,5,3,1.2499,1.2515,35,34,8,7,1.2498,1.2516,36,32,3,4,1.2497,1.2517,34,52,1,5,1.2496,1.2518,35,33,1,5,1.2495,1.2519,35,34,1,4,6BH5
2025-01-01T22:48:33.820898094Z,2025-01-01T22:48:33.820780605Z,10,1,29307,M,B,0,1.2504,8,130,15430,28101725,1.2504,1.251,8,22,1,1,1.2503,1.2511,33,32,6,5,1.2502,1.2512,35,37,2,6,1.2501,1.2513,34,33,5,5,1.25,1.2514,34,32,5,3,1.2499,1.2515,35,34,8,7,1.2498,1.2516,36,32,3,4,1.2497,1.2517,34,52,1,5,1.2496,1.2518,35,33,1,5,1.2495,1.2519,35,34,1,4,6BH5
2025-01-01T22:48:33.820906925Z,2025-01-01T22:48:33.820789513Z,10,1,29307,M,A,0,1.251,17,130,12706,28101726,1.2504,1.251,8,17,1,1,1.2503,1.2511,33,32,6,5,1.2502,1.2512,35,37,2,6,1.2501,1.2513,34,33,5,5,1.25,1.2514,34,32,5,3,1.2499,1.2515,35,34,8,7,1.2498,1.2516,36,32,3,4,1.2497,1.2517,34,52,1,5,1.2496,1.2518,35,33,1,5,1.2495,1.2519,35,34,1,4,6BH5
2025-01-01T22:48:34.820926919Z,2025-01-01T22:48:34.820796319Z,10,1,29307,M,B,0,1.2504,6,130,18157,28101735,1.2504,1.251,6,17,1,1,1.2503,1.2511,33,32,6,5,1.2502,1.2512,35,37,2,6,1.2501,1.2513,34,33,5,5,1.25,1.2514,34,32,5,3,1.2499,1.2515,35,34,8,7,1.2498,1.2516,36,32,3,4,1.2497,1.2517,34,52,1,5,1.2496,1.2518,35,33,1,5,1.2495,1.2519,35,34,1,4,6BH5
2025-01-01T22:48:34.820936303Z,2025-01-01T22:48:34.820806015Z,10,1,29307,M,A,0,1.251,13,130,12955,28101736,1.2504,1.251,6,13,1,1,1.2503,1.2511,33,32,6,5,1.2502,1.2512,35,37,2,6,1.2501,1.2513,34,33,5,5,1.25,1.2514,34,32,5,3,1.2499,1.2515,35,34,8,7,1.2498,1.2516,36,32,3,4,1.2497,1.2517,34,52,1,5,1.2496,1.2518,35,33,1,5,1.2495,1.2519,35,34,1,4,6BH5
2025-01-01T22:48:35.820974029Z,2025-01-01T22:48:35.820855239Z,10,1,29307,M,B,0,1.2504,4,130,15987,28101747,1.2504,1.251,4,13,1,1,1.2503,1.2511,33,32,6,5,1.2502,1.2512,35,37,2,6,1.2501,1.2513,34,33,5,5,1.25,1.2514,34,32,5,3,1.2499,1.2515,35,34,8,7,1.2498,1.2516,36,32,3,4,1.2497,1.2517,34,52,1,5,1.2496,1.2518,35,33,1,5,1.2495,1.2519,35,34,1,4,6BH5
2025-01-01T22:48:35.820982154Z,2025-01-01T22:48:35.820864627Z,10,1,29307,M,A,0,1.251,10,130,11963,28101748,1.2504,1.251,4,10,1,1,1.2503,1.2511,33,32,6,5,1.2502,1.2512,35,37,2,6,1.2501,1.2513,34,33,5,5,1.25,1.2514,34,32,5,3,1.2499,1.2515,35,34,8,7,1.2498,1.2516,36,32,3,4,1.2497,1.2517,34,52,1,5,1.2496,1.2518,35,33,1,5,1.2495,1.2519,35,34,1,4,6BH5
2025-01-01T22:48:36.820980296Z,2025-01-01T22:48:36.820856349Z,10,1,29307,M,B,0,1.2504,3,130,15516,28101758,1.2504,1.251,3,10,1,1,1.2503,1.2511,33,32,6,5,1.2502,1.2512,35,37,2,6,1.2501,1.2513,34,33,5,5,1.25,1.2514,34,32,5,3,1.2499,1.2515,35,34,8,7,1.2498,1.2516,36,32,3,4,1.2497,1.2517,34,52,1,5,1.2496,1.2518,35,33,1,5,1.2495,1.2519,35,34,1,4,6BH5
2025-01-01T22:48:36.820989266Z,2025-01-01T22:48:36.820865851Z,10,1,29307,M,A,0,1.251,8,130,12009,28101759,1.2504,1.251,3,8,1,1,1.2503,1.2511,33,32,6,5,1.2502,1.2512,35,37,2,6,1.2501,1.2513,34,33,5,5,1.25,1.2514,34,32,5,3,1.2499,1.2515,35,34,8,7,1.2498,1.2516,36,32,3,4,1.2497,1.2517,34,52,1,5,1.2496,1.2518,35,33,1,5,1.2495,1.2519,35,34,1,4,6BH5
2025-01-01T22:48:37.820979866Z,2025-01-01T22:48:37.820848777Z,10,1,29307,M,B,0,1.2504,2,130,16202,28101764,1.2504,1.251,2,8,1,1,1.2503,1.2511,33,32,6,5,1.2502,1.2512,35,37,2,6,1.2501,1.2513,34,33,5,5,1.25,1.2514,34,32,5,3,1.2499,1.2515,35,34,8,7,1.2498,1.2516,36,32,3,4,1.2497,1.2517,34,52,1,5,1.2496,1.2518,35,33,1,5,1.2495,1.2519,35,34,1,4,6BH5
2025-01-01T22:48:37.820989005Z,2025-01-01T22:48:37.820859529Z,10,1,29307,M,A,0,1.251,6,130,12925,28101765,1.2504,1.251,2,6,1,1,1.2503,1.2511,33,32,6,5,1.2502,1.2512,35,37,2,6,1.2501,1.2513,34,33,5,5,1.25,1.2514,34,32,5,3,1.2499,1.2515,35,34,8,7,1.2498,1.2516,36,32,3,4,1.2497,1.2517,34,52,1,5,1.2496,1.2518,35,33,1,5,1.2495,1.2519,35,34,1,4,6BH5
2025-01-01T22:48:38.821016816Z,2025-01-01T22:48:38.820888701Z,10,1,29307,M,B,0,1.2504,1,130,17886,28101769,1.2504,1.251,1,6,1,1,1.2503,1.2511,33,32,6,5,1.2502,1.2512,35,37,2,6,1.2501,1.2513,34,33,5,5,1.25,1.2514,34,32,5,3,1.2499,1.2515,35,34,8,7,1.2498,1.2516,36,32,3,4,1.2497,1.2517,34,52,1,5,1.2496,1.2518,35,33,1,5,1.2495,1.2519,35,34,1,4,6BH5
2025-01-01T22:48:38.821025732Z,2025-01-01T22:48:38.820899261Z,10,1,29307,M,A,0,1.251,4,130,12771,28101770,1.2504,1.251,1,4,1,1,1.2503,1.2511,33,32,6,5,1.2502,1.2512,35,37,2,6,1.2501,1.2513,34,33,5,5,1.25,1.2514,34,32,5,3,1.2499,1.2515,35,34,8,7,1.2498,1.2516,36,32,3,4,1.2497,1.2517,34,52,1,5,1.2496,1.2518,35,33,1,5,1.2495,1.2519,35,34,1,4,6BH5
2025-01-01T22:48:39.821022234Z,2025-01-01T22:48:39.820909503Z,10,1,29307,C,B,0,1.2504,1,130,15764,28101777,1.2503,1.251,33,4,6,1,1.2502,1.2511,35,32,2,5,1.2501,1.2512,34,37,5,6,1.25,1.2513,34,33,5,5,1.2499,1.2514,35,32,8,3,1.2498,1.2515,36,34,3,7,1.2497,1.2516,34,32,1,4,1.2496,1.2517,35,52,1,5,1.2495,1.2518,35,33,1,5,1.2494,1.2519,35,34,1,4,6BH5
2025-01-01T22:48:39.821032003Z,2025-01-01T22:48:39.820927589Z,10,1,29307,M,A,0,1.251,3,130,12096,28101778,1.2503,1.251,33,3,6,1,1.2502,1.2511,35,32,2,5,1.2501,1.2512,34,37,5,6,1.25,1.2513,34,33,5,5,1.2499,1.2514,35,32,8,3,1.2498,1.2515,36,34,3,7,1.2497,1.2516,34,32,1,4,1.2496,1.2517,35,52,1,5,1.2495,1.2518,35,33,1,5,1.2494,1.2519,35,34,1,4,6BH5
2025-01-01T22:48:40.821013979Z,2025-01-01T22:48:40.820895941Z,10,1,29307,M,A,0,1.251,2,130,15343,28101784,1.2503,1.251,33,2,6,1,1.2502,1.2511,35,32,2,5,1.2501,1.2512,34,37,5,6,1.25,1.2513,34,33,5,5,1.2499,1.2514,35,32,8,3,1.2498,1.2515,36,34,3,7,1.2497,1.2516,34,32,1,4,1.2496,1.2517,35,52,1,5,1.2495,1.2518,35,33,1,5,1.2494,1.2519,35,34,1,4,6BH5
2025-01-01T22:48:41.821015702Z,2025-01-01T22:48:41.820900479Z,10,1,29307,M,A,0,1.251,1,130,15791,28101790,1.2503,1.251,33,1,6,1,1.2502,1.2511,35,32,2,5,1.2501,1.2512,34,37,5,6,1.25,1.2513,34,33,5,5,1.2499,1.2514,35,32,8,3,1.2498,1.2515,36,34,3,7,1.2497,1.2516,34,32,1,4,1.2496,1.2517,35,52,1,5,1.2495,1.2518,35,33,1,5,1.2494,1.2519,35,34,1,4,6BH5
2025-01-01T22:48:42.821006405Z,2025-01-01T22:48:42.820897997Z,10,1,29307,C,A,0,1.251,1,130,14749,28101794,1.2503,1.2511,33,32,6,5,1.2502,1.2512,35,37,2,6,1.2501,1.2513,34,33,5,5,1.25,1.2514,34,32,5,3,1.2499,1.2515,35,34,8,7,1.2498,1.2516,36,32,3,4,1.2497,1.2517,34,52,1,5,1.2496,1.2518,35,33,1,5,1.2495,1.2519,35,34,1,4,1.2494,1.252,35,33,1,4,6BH5
2025-01-01T22:49:06.822086582Z,2025-01-01T22:49:06.821940701Z,10,1,29307,C,B,0,1.2503,6,130,17914,28101880,1.2503,1.2511,27,32,5,5,1.2502,1.2512,35,37,2,6,1.2501,1.2513,34,33,5,5,1.25,1.2514,34,32,5,3,1.2499,1.2515,35,34,8,7,1.2498,1.2516,36,32,3,4,1.2497,1.2517,34,52,1,5,1.2496,1.2518,35,33,1,5,1.2495,1.2519,35,34,1,4,1.2494,1.252,35,33,1,4,6BH5
2025-01-01T22:49:07.821980747Z,2025-01-01T22:49:07.821865191Z,10,1,29307,C,B,0,1.2503,5,130,16231,28101885,1.2503,1.2511,22,32,4,5,1.2502,1.2512,35,37,2,6,1.2501,1.2513,34,33,5,5,1.25,1.2514,34,32,5,3,1.2499,1.2515,35,34,8,7,1.2498,1.2516,36,32,3,4,1.2497,1.2517,34,52,1,5,1.2496,1.2518,35,33,1,5,1.2495,1.2519,35,34,1,4,1.2494,1.252,35,33,1,4,6BH5
2025-01-01T22:49:13.822000341Z,2025-01-01T22:49:13.821879983Z,10,1,29307,M,B,0,1.2503,2,130,15663,28101926,1.2503,1.2511,18,32,4,5,1.2502,1.2512,35,37,2,6,1.2501,1.2513,34,33,5,5,1.25,1.2514,34,32,5,3,1.2499,1.2515,35,34,8,7,1.2498,1.2516,36,32,3,4,1.2497,1.2517,34,52,1,5,1.2496,1.2518,35,33,1,5,1.2495,1.2519,35,34,1,4,1.2494,1.252,35,33,1,4,6BH5
2025-01-01T22:49:14.822031370Z,2025-01-01T22:49:14.821919255Z,10,1,29307,C,B,0,1.2503,2,130,14648,28101933,1.2503,1.2511,16,32,3,5,1.2502,1.2512,35,37,2,6,1.2501,1.2513,34,33,5,5,1.25,1.2514,34,32,5,3,1.2499,1.2515,35,34,8,7,1.2498,1.2516,36,32,3,4,1.2497,1.2517,34,52,1,5,1.2496,1.2518,35,33,1,5,1.2495,1.2519,35,34,1,4,1.2494,1.252,35,33,1,4,6BH5
2025-01-01T22:49:14.822042720Z,2025-01-01T22:49:14.821931583Z,10,1,29307,M,B,0,1.2503,4,130,13075,28101934,1.2503,1.2511,14,32,3,5,1.2502,1.2512,35,37,2,6,1.2501,1.2513,34,33,5,5,1.25,1.2514,34,32,5,3,1.2499,1.2515,35,34,8,7,1.2498,1.2516,36,32,3,4,1.2497,1.2517,34,52,1,5,1.2496,1.2518,35,33,1,5,1.2495,1.2519,35,34,1,4,1.2494,1.252,35,33,1,4,6BH5
2025-01-01T22:49:15.822019513Z,2025-01-01T22:49:15.821905903Z,10,1,29307,M,B,0,1.2503,1,130,15115,28101944,1.2503,1.2511,11,32,3,5,1.2502,1.2512,35,37,2,6,1.2501,1.2513,34,33,5,5,1.25,1.2514,34,32,5,3,1.2499,1.2515,35,34,8,7,1.2498,1.2516,36,32,3,4,1.2497,1.2517,34,52,1,5,1.2496,1.2518,35,33,1,5,1.2495,1.2519,35,34,1,4,1.2494,1.252,35,33,1,4,6BH5
2025-01-01T22:49:15.822029343Z,2025-01-01T22:49:15.821916291Z,10,1,29307,C,A,0,1.2511,6,130,12900,28101945,1.2503,1.2511,11,26,3,4,1.2502,1.2512,35,37,2,6,1.2501,1.2513,34,33,5,5,1.25,1.2514,34,32,5,3,1.2499,1.2515,35,34,8,7,1.2498,1.2516,36,32,3,4,1.2497,1.2517,34,52,1,5,1.2496,1.2518,35,33,1,5,1.2495,1.2519,35,34,1,4,1.2494,1.252,35,33,1,4,6BH5
2025-01-01T22:49:16.822035528Z,2025-01-01T22:49:16.821926151Z,10,1,29307,C,B,0,1.2503,1,130,15447,28101952,1.2503,1.2511,10,26,2,4,1.2502,1.2512,35,37,2,6,1.2501,1.2513,34,33,5,5,1.25,1.2514,34,32,5,3,1.2499,1.2515,35,34,8,7,1.2498,1.2516,36,32,3,4,1.2497,1.2517,34,52,1,5,1.2496,1.2518,35,33,1,5,1.2495,1.2519,35,34,1,4,1.2494,1.252,35,33,1,4,6BH5
2025-01-01T22:49:16.822047700Z,2025-01-01T22:49:16.821939667Z,10,1,29307,M,B,0,1.2503,7,130,12934,28101953,1.2503,1.2511,8,26,2,4,1.2502,1.2512,35,37,2,6,1.2501,1.2513,34,33,5,5,1.25,1.2514,34,32,5,3,1.2499,1.2515,35,34,8,7,1.2498,1.2516,36,32,3,4,1.2497,1.2517,34,52,1,5,1.2496,1.2518,35,33,1,5,1.2495,1.2519,35,34,1,4,1.2494,1.252,35,33,1,4,6BH5
2025-01-01T22:49:17.822035565Z,2025-01-01T22:49:17.821917925Z,10,1,29307,M,B,0,1.2503,5,130,15194,28101960,1.2503,1.2511,6,26,2,4,1.2502,1.2512,35,37,2,6,1.2501,1.2513,34,33,5,5,1.25,1.2514,34,32,5,3,1.2499,1.2515,35,34,8,7,1.2498,1.2516,36,32,3,4,1.2497,1.2517,34,52,1,5,1.2496,1.2518,35,33,1,5,1.2495,1.2519,35,34,1,4,1.2494,1.252,35,33,1,4,6BH5
2025-01-01T22:49:18.822088725Z,2025-01-01T22:49:18.821964159Z,10,1,29307,M,B,0,1.2503,3,130,16213,28101967,1.2503,1.2511,4,26,2,4,1.2502,1.2512,35,37,2,6,1.2501,1.2513,34,33,5,5,1.25,1.2514,34,32,5,3,1.2499,1.2515,35,34,8,7,1.2498,1.2516,36,32,3,4,1.2497,1.2517,34,52,1,5,1.2496,1.2518,35,33,1,5,1.2495,1.2519,35,34,1,4,1.2494,1.252,35,33,1,4,6BH5
2025-01-01T22:49:19.822092755Z,2025-01-01T22:49:19.821976971Z,10,1,29307,M,B,0,1.2503,2,130,14631,28101975,1.2503,1.2511,3,26,2,4,1.2502,1.2512,35,37,2,6,1.2501,1.2513,34,33,5,5,1.25,1.2514,34,32,5,3,1.2499,1.2515,35,34,8,7,1.2498,1.2516,36,32,3,4,1.2497,1.2517,34,52,1,5,1.2496,1.2518,35,33,1,5,1.2495,1.2519,35,34,1,4,1.2494,1.252,35,33,1,4,6BH5
2025-01-01T22:49:20.822106598Z,2025-01-01T22:49:20.821997701Z,10,1,29307,M,B,0,1.2503,1,130,14907,28101983,1.2503,1.2511,2,26,2,4,1.2502,1.2512,35,37,2,6,1.2501,1.2513,34,33,5,5,1.25,1.2514,34,32,5,3,1.2499,1.2515,35,34,8,7,1.2498,1.2516,36,32,3,4,1.2497,1.2517,34,52,1,5,1.2496,1.2518,35,33,1,5,1.2495,1.2519,35,34,1,4,1.2494,1.252,35,33,1,4,6BH5
2025-01-01T22:49:21.822183030Z,2025-01-01T22:49:21.822069903Z,10,1,29307,C,B,0,1.2503,1,130,16289,28101992,1.2503,1.2511,1,26,1,4,1.2502,1.2512,35,37,2,6,1.2501,1.2513,34,33,5,5,1.25,1.2514,34,32,5,3,1.2499,1.2515,35,34,8,7,1.2498,1.2516,36,32,3,4,1.2497,1.2517,34,52,1,5,1.2496,1.2518,35,33,1,5,1.2495,1.2519,35,34,1,4,1.2494,1.252,35,33,1,4,6BH5
2025-01-01T22:49:22.822229903Z,2025-01-01T22:49:22.822116043Z,10,1,29307,C,B,0,1.2503,1,130,15899,28101998,1.2502,1.2511,35,26,2,4,1.2501,1.2512,34,37,5,6,1.25,1.2513,34,33,5,5,1.2499,1.2514,35,32,8,3,1.2498,1.2515,36,34,3,7,1.2497,1.2516,34,32,1,4,1.2496,1.2517,35,52,1,5,1.2495,1.2518,35,33,1,5,1.2494,1.2519,35,34,1,4,1.2493,1.252,35,33,1,4,6BH5
2025-01-01T22:49:22.822238021Z,2025-01-01T22:49:22.822126967Z,10,1,29307,M,A,0,1.2511,1,130,11843,28101999,1.2502,1.2511,35,21,2,4,1.2501,1.2512,34,37,5,6,1.25,1.2513,34,33,5,5,1.2499,1.2514,35,32,8,3,1.2498,1.2515,36,34,3,7,1.2497,1.2516,34,32,1,4,1.2496,1.2517,35,52,1,5,1.2495,1.2518,35,33,1,5,1.2494,1.2519,35,34,1,4,1.2493,1.252,35,33,1,4,6BH5
2025-01-01T22:49:23.822226345Z,2025-01-01T22:49:23.822118715Z,10,1,29307,C,A,0,1.2511,1,130,16142,28102005,1.2502,1.2511,35,20,2,3,1.2501,1.2512,34,37,5,6,1.25,1.2513,34,33,5,5,1.2499,1.2514,35,32,8,3,1.2498,1.2515,36,34,3,7,1.2497,1.2516,34,32,1,4,1.2496,1.2517,35,52,1,5,1.2495,1.2518,35,33,1,5,1.2494,1.2519,35,34,1,4,1.2493,1.252,35,33,1,4,6BH5
2025-01-01T22:49:23.822237695Z,2025-01-01T22:49:23.822128449Z,10,1,29307,M,A,0,1.2511,1,130,13154,28102006,1.2502,1.2511,35,17,2,3,1.2501,1.2512,34,37,5,6,1.25,1.2513,34,33,5,5,1.2499,1.2514,35,32,8,3,1.2498,1.2515,36,34,3,7,1.2497,1.2516,34,32,1,4,1.2496,1.2517,35,52,1,5,1.2495,1.2518,35,33,1,5,1.2494,1.2519,35,34,1,4,1.2493,1.252,35,33,1,4,6BH5
2025-01-01T22:49:24.822241111Z,2025-01-01T22:49:24.822134477Z,10,1,29307,C,A,0,1.2511,1,130,15737,28102012,1.2502,1.2511,35,16,2,2,1.2501,1.2512,34,37,5,6,1.25,1.2513,34,33,5,5,1.2499,1.2514,35,32,8,3,1.2498,1.2515,36,34,3,7,1.2497,1.2516,34,32,1,4,1.2496,1.2517,35,52,1,5,1.2495,1.2518,35,33,1,5,1.2494,1.2519,35,34,1,4,1.2493,1.252,35,33,1,4,6BH5
2025-01-01T22:49:24.822251056Z,2025-01-01T22:49:24.822144499Z,10,1,29307,M,A,0,1.2511,1,130,12748,28102013,1.2502,1.2511,35,13,2,2,1.2501,1.2512,34,37,5,6,1.25,1.2513,34,33,5,5,1.2499,1.2514,35,32,8,3,1.2498,1.2515,36,34,3,7,1.2497,1.2516,34,32,1,4,1.2496,1.2517,35,52,1,5,1.2495,1.2518,35,33,1,5,1.2494,1.2519,35,34,1,4,1.2493,1.252,35,33,1,4,6BH5
2025-01-01T22:49:25.822280391Z,2025-01-01T22:49:25.822171357Z,10,1,29307,C,A,0,1.2511,1,130,15253,28102020,1.2502,1.2511,35,12,2,1,1.2501,1.2512,34,37,5,6,1.25,1.2513,34,33,5,5,1.2499,1.2514,35,32,8,3,1.2498,1.2515,36,34,3,7,1.2497,1.2516,34,32,1,4,1.2496,1.2517,35,52,1,5,1.2495,1.2518,35,33,1,5,1.2494,1.2519,35,34,1,4,1.2493,1.252,35,33,1,4,6BH5
2025-01-01T22:49:25.822290643Z,2025-01-01T22:49:25.822181165Z,10,1,29307,M,A,0,1.2511,10,130,12843,28102021,1.2502,1.2511,35,10,2,1,1.2501,1.2512,34,37,5,6,1.25,1.2513,34,33,5,5,1.2499,1.2514,35,32,8,3,1.2498,1.2515,36,34,3,7,1.2497,1.2516,34,32,1,4,1.2496,1.2517,35,52,1,5,1.2495,1.2518,35,33,1,5,1.2494,1.2519,35,34,1,4,1.2493,1.252,35,33,1,4,6BH5
2025-01-01T22:49:26.822307331Z,2025-01-01T22:49:26.822196331Z,10,1,29307,M,A,0,1.2511,8,130,15337,28102028,1.2502,1.2511,35,8,2,1,1.2501,1.2512,34,37,5,6,1.25,1.2513,34,33,5,5,1.2499,1.2514,35,32,8,3,1.2498,1.2515,36,34,3,7,1.2497,1.2516,34,32,1,4,1.2496,1.2517,35,52,1,5,1.2495,1.2518,35,33,1,5,1.2494,1.2519,35,34,1,4,1.2493,1.252,35,33,1,4,6BH5
2025-01-01T22:49:27.822359485Z,2025-01-01T22:49:27.822246107Z,10,1,29307,M,A,0,1.2511,6,130,15343,28102037,1.2502,1.2511,35,6,2,1,1.2501,1.2512,34,37,5,6,1.25,1.2513,34,33,5,5,1.2499,1.2514,35,32,8,3,1.2498,1.2515,36,34,3,7,1.2497,1.2516,34,32,1,4,1.2496,1.2517,35,52,1,5,1.2495,1.2518,35,33,1,5,1.2494,1.2519,35,34,1,4,1.2493,1.252,35,33,1,4,6BH5
2025-01-01T22:49:28.822394630Z,2025-01-01T22:49:28.822280391Z,10,1,29307,M,A,0,1.2511,4,130,15500,28102042,1.2502,1.2511,35,4,2,1,1.2501,1.2512,34,37,5,6,1.25,1.2513,34,33,5,5,1.2499,1.2514,35,32,8,3,1.2498,1.2515,36,34,3,7,1.2497,1.2516,34,32,1,4,1.2496,1.2517,35,52,1,5,1.2495,1.2518,35,33,1,5,1.2494,1.2519,35,34,1,4,1.2493,1.252,35,33,1,4,6BH5
2025-01-01T22:49:29.822450072Z,2025-01-01T22:49:29.822332549Z,10,1,29307,M,A,0,1.2511,3,130,15775,28102047,1.2502,1.2511,35,3,2,1,1.2501,1.2512,34,37,5,6,1.25,1.2513,34,33,5,5,1.2499,1.2514,35,32,8,3,1.2498,1.2515,36,34,3,7,1.2497,1.2516,34,32,1,4,1.2496,1.2517,35,52,1,5,1.2495,1.2518,35,33,1,5,1.2494,1.2519,35,34,1,4,1.2493,1.252,35,33,1,4,6BH5
2025-01-01T22:49:30.822484046Z,2025-01-01T22:49:30.822358885Z,10,1,29307,M,A,0,1.2511,2,130,16097,28102053,1.2502,1.2511,35,2,2,1,1.2501,1.2512,34,37,5,6,1.25,1.2513,34,33,5,5,1.2499,1.2514,35,32,8,3,1.2498,1.2515,36,34,3,7,1.2497,1.2516,34,32,1,4,1.2496,1.2517,35,52,1,5,1.2495,1.2518,35,33,1,5,1.2494,1.2519,35,34,1,4,1.2493,1.252,35,33,1,4,6BH5
2025-01-01T22:49:31.822568658Z,2025-01-01T22:49:31.822417559Z,10,1,29307,M,A,0,1.2511,1,130,16260,28102058,1.2502,1.2511,35,1,2,1,1.2501,1.2512,34,37,5,6,1.25,1.2513,34,33,5,5,1.2499,1.2514,35,32,8,3,1.2498,1.2515,36,34,3,7,1.2497,1.2516,34,32,1,4,1.2496,1.2517,35,52,1,5,1.2495,1.2518,35,33,1,5,1.2494,1.2519,35,34,1,4,1.2493,1.252,35,33,1,4,6BH5
